[2025-06-10T16:49:06.001+0200] {local_task_job_runner.py:123} INFO - ::group::Pre task execution logs
[2025-06-10T16:49:06.005+0200] {taskinstance.py:2614} INFO - Dependencies all met for dep_context=non-requeueable deps ti=<TaskInstance: case4.send_success_email manual__2025-06-10T14:48:55.592923+00:00 [queued]>
[2025-06-10T16:49:06.008+0200] {taskinstance.py:2614} INFO - Dependencies all met for dep_context=requeueable deps ti=<TaskInstance: case4.send_success_email manual__2025-06-10T14:48:55.592923+00:00 [queued]>
[2025-06-10T16:49:06.008+0200] {taskinstance.py:2867} INFO - Starting attempt 1 of 1
[2025-06-10T16:49:06.012+0200] {taskinstance.py:2890} INFO - Executing <Task(EmailOperator): send_success_email> on 2025-06-10 14:48:55.592923+00:00
[2025-06-10T16:49:06.015+0200] {standard_task_runner.py:72} INFO - Started process 46819 to run task
[2025-06-10T16:49:06.017+0200] {standard_task_runner.py:104} INFO - Running: ['airflow', 'tasks', 'run', 'case4', 'send_success_email', 'manual__2025-06-10T14:48:55.592923+00:00', '--job-id', '60', '--raw', '--subdir', 'DAGS_FOLDER/case4.py', '--cfg-path', '/var/folders/sj/kmk_wl3517d377606n_z382h0000gp/T/tmpk6j2d3m2']
[2025-06-10T16:49:06.019+0200] {standard_task_runner.py:105} INFO - Job 60: Subtask send_success_email
[2025-06-10T16:49:06.055+0200] {task_command.py:467} INFO - Running <TaskInstance: case4.send_success_email manual__2025-06-10T14:48:55.592923+00:00 [running]> on host LGLXN9TVJX
[2025-06-10T16:49:06.076+0200] {taskinstance.py:3134} INFO - Exporting env vars: AIRFLOW_CTX_DAG_EMAIL='tayfun.simsek@mhp.com' AIRFLOW_CTX_DAG_OWNER='airflow' AIRFLOW_CTX_DAG_ID='case4' AIRFLOW_CTX_TASK_ID='send_success_email' AIRFLOW_CTX_EXECUTION_DATE='2025-06-10T14:48:55.592923+00:00' AIRFLOW_CTX_TRY_NUMBER='1' AIRFLOW_CTX_DAG_RUN_ID='manual__2025-06-10T14:48:55.592923+00:00'
[2025-06-10T16:49:06.077+0200] {taskinstance.py:732} INFO - ::endgroup::
[2025-06-10T16:49:06.090+0200] {logging_mixin.py:190} WARNING - /Users/tsimsek/Library/Python/3.9/lib/python/site-packages/airflow/utils/email.py:155 RemovedInAirflow3Warning: Fetching SMTP credentials from configuration variables will be deprecated in a future release. Please set credentials using a connection instead.
[2025-06-10T16:49:06.090+0200] {configuration.py:1074} WARNING - section/key [smtp/smtp_user] not found in config
[2025-06-10T16:49:06.090+0200] {email.py:272} INFO - Email alerting: attempt 1
[2025-06-10T16:49:06.092+0200] {taskinstance.py:3313} ERROR - Task failed with exception
Traceback (most recent call last):
  File "/Users/tsimsek/Library/Python/3.9/lib/python/site-packages/airflow/models/taskinstance.py", line 768, in _execute_task
    result = _execute_callable(context=context, **execute_callable_kwargs)
  File "/Users/tsimsek/Library/Python/3.9/lib/python/site-packages/airflow/models/taskinstance.py", line 734, in _execute_callable
    return ExecutionCallableRunner(
  File "/Users/tsimsek/Library/Python/3.9/lib/python/site-packages/airflow/utils/operator_helpers.py", line 252, in run
    return self.func(*args, **kwargs)
  File "/Users/tsimsek/Library/Python/3.9/lib/python/site-packages/airflow/models/baseoperator.py", line 424, in wrapper
    return func(self, *args, **kwargs)
  File "/Users/tsimsek/Library/Python/3.9/lib/python/site-packages/airflow/operators/email.py", line 79, in execute
    send_email(
  File "/Users/tsimsek/Library/Python/3.9/lib/python/site-packages/airflow/utils/email.py", line 80, in send_email
    return backend(
  File "/Users/tsimsek/Library/Python/3.9/lib/python/site-packages/airflow/utils/email.py", line 155, in send_email_smtp
    send_mime_email(e_from=mail_from, e_to=recipients, mime_msg=msg, conn_id=conn_id, dryrun=dryrun)
  File "/Users/tsimsek/Library/Python/3.9/lib/python/site-packages/airflow/utils/email.py", line 274, in send_mime_email
    smtp_conn = _get_smtp_connection(smtp_host, smtp_port, smtp_timeout, smtp_ssl)
  File "/Users/tsimsek/Library/Python/3.9/lib/python/site-packages/airflow/utils/email.py", line 318, in _get_smtp_connection
    return smtplib.SMTP(host=host, port=port, timeout=timeout)
  File "/Applications/Xcode.app/Contents/Developer/Library/Frameworks/Python3.framework/Versions/3.9/lib/python3.9/smtplib.py", line 255, in __init__
    (code, msg) = self.connect(host, port)
  File "/Applications/Xcode.app/Contents/Developer/Library/Frameworks/Python3.framework/Versions/3.9/lib/python3.9/smtplib.py", line 341, in connect
    self.sock = self._get_socket(host, port, self.timeout)
  File "/Applications/Xcode.app/Contents/Developer/Library/Frameworks/Python3.framework/Versions/3.9/lib/python3.9/smtplib.py", line 312, in _get_socket
    return socket.create_connection((host, port), timeout,
  File "/Applications/Xcode.app/Contents/Developer/Library/Frameworks/Python3.framework/Versions/3.9/lib/python3.9/socket.py", line 843, in create_connection
    raise err
  File "/Applications/Xcode.app/Contents/Developer/Library/Frameworks/Python3.framework/Versions/3.9/lib/python3.9/socket.py", line 831, in create_connection
    sock.connect(sa)
ConnectionRefusedError: [Errno 61] Connection refused
[2025-06-10T16:49:06.157+0200] {taskinstance.py:1226} INFO - Marking task as FAILED. dag_id=case4, task_id=send_success_email, run_id=manual__2025-06-10T14:48:55.592923+00:00, execution_date=20250610T144855, start_date=20250610T144906, end_date=20250610T144906
[2025-06-10T16:49:06.161+0200] {configuration.py:1074} WARNING - section/key [smtp/smtp_user] not found in config
[2025-06-10T16:49:06.161+0200] {email.py:272} INFO - Email alerting: attempt 1
[2025-06-10T16:49:06.163+0200] {configuration.py:1074} WARNING - section/key [smtp/smtp_user] not found in config
[2025-06-10T16:49:06.163+0200] {email.py:272} INFO - Email alerting: attempt 1
[2025-06-10T16:49:06.164+0200] {taskinstance.py:1235} ERROR - Failed to send email to: ['tayfun.simsek@mhp.com']
Traceback (most recent call last):
  File "/Users/tsimsek/Library/Python/3.9/lib/python/site-packages/airflow/models/taskinstance.py", line 274, in _run_raw_task
    TaskInstance._execute_task_with_callbacks(
  File "/Users/tsimsek/Library/Python/3.9/lib/python/site-packages/airflow/models/taskinstance.py", line 3161, in _execute_task_with_callbacks
    result = self._execute_task(context, task_orig)
  File "/Users/tsimsek/Library/Python/3.9/lib/python/site-packages/airflow/models/taskinstance.py", line 3185, in _execute_task
    return _execute_task(self, context, task_orig)
  File "/Users/tsimsek/Library/Python/3.9/lib/python/site-packages/airflow/models/taskinstance.py", line 768, in _execute_task
    result = _execute_callable(context=context, **execute_callable_kwargs)
  File "/Users/tsimsek/Library/Python/3.9/lib/python/site-packages/airflow/models/taskinstance.py", line 734, in _execute_callable
    return ExecutionCallableRunner(
  File "/Users/tsimsek/Library/Python/3.9/lib/python/site-packages/airflow/utils/operator_helpers.py", line 252, in run
    return self.func(*args, **kwargs)
  File "/Users/tsimsek/Library/Python/3.9/lib/python/site-packages/airflow/models/baseoperator.py", line 424, in wrapper
    return func(self, *args, **kwargs)
  File "/Users/tsimsek/Library/Python/3.9/lib/python/site-packages/airflow/operators/email.py", line 79, in execute
    send_email(
  File "/Users/tsimsek/Library/Python/3.9/lib/python/site-packages/airflow/utils/email.py", line 80, in send_email
    return backend(
  File "/Users/tsimsek/Library/Python/3.9/lib/python/site-packages/airflow/utils/email.py", line 155, in send_email_smtp
    send_mime_email(e_from=mail_from, e_to=recipients, mime_msg=msg, conn_id=conn_id, dryrun=dryrun)
  File "/Users/tsimsek/Library/Python/3.9/lib/python/site-packages/airflow/utils/email.py", line 274, in send_mime_email
    smtp_conn = _get_smtp_connection(smtp_host, smtp_port, smtp_timeout, smtp_ssl)
  File "/Users/tsimsek/Library/Python/3.9/lib/python/site-packages/airflow/utils/email.py", line 318, in _get_smtp_connection
    return smtplib.SMTP(host=host, port=port, timeout=timeout)
  File "/Applications/Xcode.app/Contents/Developer/Library/Frameworks/Python3.framework/Versions/3.9/lib/python3.9/smtplib.py", line 255, in __init__
    (code, msg) = self.connect(host, port)
  File "/Applications/Xcode.app/Contents/Developer/Library/Frameworks/Python3.framework/Versions/3.9/lib/python3.9/smtplib.py", line 341, in connect
    self.sock = self._get_socket(host, port, self.timeout)
  File "/Applications/Xcode.app/Contents/Developer/Library/Frameworks/Python3.framework/Versions/3.9/lib/python3.9/smtplib.py", line 312, in _get_socket
    return socket.create_connection((host, port), timeout,
  File "/Applications/Xcode.app/Contents/Developer/Library/Frameworks/Python3.framework/Versions/3.9/lib/python3.9/socket.py", line 843, in create_connection
    raise err
  File "/Applications/Xcode.app/Contents/Developer/Library/Frameworks/Python3.framework/Versions/3.9/lib/python3.9/socket.py", line 831, in create_connection
    sock.connect(sa)
ConnectionRefusedError: [Errno 61] Connection refused

During handling of the above exception, another exception occurred:

Traceback (most recent call last):
  File "/Users/tsimsek/Library/Python/3.9/lib/python/site-packages/airflow/models/taskinstance.py", line 1443, in _email_alert
    send_email(task.email, subject, html_content)
  File "/Users/tsimsek/Library/Python/3.9/lib/python/site-packages/airflow/utils/email.py", line 80, in send_email
    return backend(
  File "/Users/tsimsek/Library/Python/3.9/lib/python/site-packages/airflow/utils/email.py", line 155, in send_email_smtp
    send_mime_email(e_from=mail_from, e_to=recipients, mime_msg=msg, conn_id=conn_id, dryrun=dryrun)
  File "/Users/tsimsek/Library/Python/3.9/lib/python/site-packages/airflow/utils/email.py", line 274, in send_mime_email
    smtp_conn = _get_smtp_connection(smtp_host, smtp_port, smtp_timeout, smtp_ssl)
  File "/Users/tsimsek/Library/Python/3.9/lib/python/site-packages/airflow/utils/email.py", line 318, in _get_smtp_connection
    return smtplib.SMTP(host=host, port=port, timeout=timeout)
  File "/Applications/Xcode.app/Contents/Developer/Library/Frameworks/Python3.framework/Versions/3.9/lib/python3.9/smtplib.py", line 255, in __init__
    (code, msg) = self.connect(host, port)
  File "/Applications/Xcode.app/Contents/Developer/Library/Frameworks/Python3.framework/Versions/3.9/lib/python3.9/smtplib.py", line 341, in connect
    self.sock = self._get_socket(host, port, self.timeout)
  File "/Applications/Xcode.app/Contents/Developer/Library/Frameworks/Python3.framework/Versions/3.9/lib/python3.9/smtplib.py", line 312, in _get_socket
    return socket.create_connection((host, port), timeout,
  File "/Applications/Xcode.app/Contents/Developer/Library/Frameworks/Python3.framework/Versions/3.9/lib/python3.9/socket.py", line 843, in create_connection
    raise err
  File "/Applications/Xcode.app/Contents/Developer/Library/Frameworks/Python3.framework/Versions/3.9/lib/python3.9/socket.py", line 831, in create_connection
    sock.connect(sa)
ConnectionRefusedError: [Errno 61] Connection refused

During handling of the above exception, another exception occurred:

Traceback (most recent call last):
  File "/Users/tsimsek/Library/Python/3.9/lib/python/site-packages/airflow/models/taskinstance.py", line 1233, in _handle_failure
    task_instance.email_alert(error, failure_context["task"])
  File "/Users/tsimsek/Library/Python/3.9/lib/python/site-packages/airflow/models/taskinstance.py", line 3611, in email_alert
    _email_alert(task_instance=self, exception=exception, task=task)
  File "/Users/tsimsek/Library/Python/3.9/lib/python/site-packages/airflow/models/taskinstance.py", line 1445, in _email_alert
    send_email(task.email, subject, html_content_err)
  File "/Users/tsimsek/Library/Python/3.9/lib/python/site-packages/airflow/utils/email.py", line 80, in send_email
    return backend(
  File "/Users/tsimsek/Library/Python/3.9/lib/python/site-packages/airflow/utils/email.py", line 155, in send_email_smtp
    send_mime_email(e_from=mail_from, e_to=recipients, mime_msg=msg, conn_id=conn_id, dryrun=dryrun)
  File "/Users/tsimsek/Library/Python/3.9/lib/python/site-packages/airflow/utils/email.py", line 274, in send_mime_email
    smtp_conn = _get_smtp_connection(smtp_host, smtp_port, smtp_timeout, smtp_ssl)
  File "/Users/tsimsek/Library/Python/3.9/lib/python/site-packages/airflow/utils/email.py", line 318, in _get_smtp_connection
    return smtplib.SMTP(host=host, port=port, timeout=timeout)
  File "/Applications/Xcode.app/Contents/Developer/Library/Frameworks/Python3.framework/Versions/3.9/lib/python3.9/smtplib.py", line 255, in __init__
    (code, msg) = self.connect(host, port)
  File "/Applications/Xcode.app/Contents/Developer/Library/Frameworks/Python3.framework/Versions/3.9/lib/python3.9/smtplib.py", line 341, in connect
    self.sock = self._get_socket(host, port, self.timeout)
  File "/Applications/Xcode.app/Contents/Developer/Library/Frameworks/Python3.framework/Versions/3.9/lib/python3.9/smtplib.py", line 312, in _get_socket
    return socket.create_connection((host, port), timeout,
  File "/Applications/Xcode.app/Contents/Developer/Library/Frameworks/Python3.framework/Versions/3.9/lib/python3.9/socket.py", line 843, in create_connection
    raise err
  File "/Applications/Xcode.app/Contents/Developer/Library/Frameworks/Python3.framework/Versions/3.9/lib/python3.9/socket.py", line 831, in create_connection
    sock.connect(sa)
ConnectionRefusedError: [Errno 61] Connection refused
[2025-06-10T16:49:06.168+0200] {taskinstance.py:341} INFO - ::group::Post task execution logs
[2025-06-10T16:49:06.168+0200] {standard_task_runner.py:124} ERROR - Failed to execute job 60 for task send_success_email ([Errno 61] Connection refused; 46819)
Traceback (most recent call last):
  File "/Users/tsimsek/Library/Python/3.9/lib/python/site-packages/airflow/task/task_runner/standard_task_runner.py", line 117, in _start_by_fork
    ret = args.func(args, dag=self.dag)
  File "/Users/tsimsek/Library/Python/3.9/lib/python/site-packages/airflow/cli/cli_config.py", line 49, in command
    return func(*args, **kwargs)
  File "/Users/tsimsek/Library/Python/3.9/lib/python/site-packages/airflow/utils/cli.py", line 116, in wrapper
    return f(*args, **kwargs)
  File "/Users/tsimsek/Library/Python/3.9/lib/python/site-packages/airflow/cli/commands/task_command.py", line 483, in task_run
    task_return_code = _run_task_by_selected_method(args, _dag, ti)
  File "/Users/tsimsek/Library/Python/3.9/lib/python/site-packages/airflow/cli/commands/task_command.py", line 256, in _run_task_by_selected_method
    return _run_raw_task(args, ti)
  File "/Users/tsimsek/Library/Python/3.9/lib/python/site-packages/airflow/cli/commands/task_command.py", line 341, in _run_raw_task
    return ti._run_raw_task(
  File "/Users/tsimsek/Library/Python/3.9/lib/python/site-packages/airflow/utils/session.py", line 97, in wrapper
    return func(*args, session=session, **kwargs)
  File "/Users/tsimsek/Library/Python/3.9/lib/python/site-packages/airflow/models/taskinstance.py", line 3006, in _run_raw_task
    return _run_raw_task(
  File "/Users/tsimsek/Library/Python/3.9/lib/python/site-packages/airflow/models/taskinstance.py", line 274, in _run_raw_task
    TaskInstance._execute_task_with_callbacks(
  File "/Users/tsimsek/Library/Python/3.9/lib/python/site-packages/airflow/models/taskinstance.py", line 3161, in _execute_task_with_callbacks
    result = self._execute_task(context, task_orig)
  File "/Users/tsimsek/Library/Python/3.9/lib/python/site-packages/airflow/models/taskinstance.py", line 3185, in _execute_task
    return _execute_task(self, context, task_orig)
  File "/Users/tsimsek/Library/Python/3.9/lib/python/site-packages/airflow/models/taskinstance.py", line 768, in _execute_task
    result = _execute_callable(context=context, **execute_callable_kwargs)
  File "/Users/tsimsek/Library/Python/3.9/lib/python/site-packages/airflow/models/taskinstance.py", line 734, in _execute_callable
    return ExecutionCallableRunner(
  File "/Users/tsimsek/Library/Python/3.9/lib/python/site-packages/airflow/utils/operator_helpers.py", line 252, in run
    return self.func(*args, **kwargs)
  File "/Users/tsimsek/Library/Python/3.9/lib/python/site-packages/airflow/models/baseoperator.py", line 424, in wrapper
    return func(self, *args, **kwargs)
  File "/Users/tsimsek/Library/Python/3.9/lib/python/site-packages/airflow/operators/email.py", line 79, in execute
    send_email(
  File "/Users/tsimsek/Library/Python/3.9/lib/python/site-packages/airflow/utils/email.py", line 80, in send_email
    return backend(
  File "/Users/tsimsek/Library/Python/3.9/lib/python/site-packages/airflow/utils/email.py", line 155, in send_email_smtp
    send_mime_email(e_from=mail_from, e_to=recipients, mime_msg=msg, conn_id=conn_id, dryrun=dryrun)
  File "/Users/tsimsek/Library/Python/3.9/lib/python/site-packages/airflow/utils/email.py", line 274, in send_mime_email
    smtp_conn = _get_smtp_connection(smtp_host, smtp_port, smtp_timeout, smtp_ssl)
  File "/Users/tsimsek/Library/Python/3.9/lib/python/site-packages/airflow/utils/email.py", line 318, in _get_smtp_connection
    return smtplib.SMTP(host=host, port=port, timeout=timeout)
  File "/Applications/Xcode.app/Contents/Developer/Library/Frameworks/Python3.framework/Versions/3.9/lib/python3.9/smtplib.py", line 255, in __init__
    (code, msg) = self.connect(host, port)
  File "/Applications/Xcode.app/Contents/Developer/Library/Frameworks/Python3.framework/Versions/3.9/lib/python3.9/smtplib.py", line 341, in connect
    self.sock = self._get_socket(host, port, self.timeout)
  File "/Applications/Xcode.app/Contents/Developer/Library/Frameworks/Python3.framework/Versions/3.9/lib/python3.9/smtplib.py", line 312, in _get_socket
    return socket.create_connection((host, port), timeout,
  File "/Applications/Xcode.app/Contents/Developer/Library/Frameworks/Python3.framework/Versions/3.9/lib/python3.9/socket.py", line 843, in create_connection
    raise err
  File "/Applications/Xcode.app/Contents/Developer/Library/Frameworks/Python3.framework/Versions/3.9/lib/python3.9/socket.py", line 831, in create_connection
    sock.connect(sa)
ConnectionRefusedError: [Errno 61] Connection refused
[2025-06-10T16:49:06.236+0200] {local_task_job_runner.py:266} INFO - Task exited with return code 1
[2025-06-10T16:49:06.244+0200] {taskinstance.py:3901} INFO - 0 downstream tasks scheduled from follow-on schedule check
[2025-06-10T16:49:06.244+0200] {local_task_job_runner.py:245} INFO - ::endgroup::
