[2025-06-10T16:43:45.702+0200] {local_task_job_runner.py:123} INFO - ::group::Pre task execution logs
[2025-06-10T16:43:45.707+0200] {taskinstance.py:2614} INFO - Dependencies all met for dep_context=non-requeueable deps ti=<TaskInstance: case4.data_quality_check manual__2025-06-10T14:42:33.619738+00:00 [queued]>
[2025-06-10T16:43:45.710+0200] {taskinstance.py:2614} INFO - Dependencies all met for dep_context=requeueable deps ti=<TaskInstance: case4.data_quality_check manual__2025-06-10T14:42:33.619738+00:00 [queued]>
[2025-06-10T16:43:45.710+0200] {taskinstance.py:2867} INFO - Starting attempt 1 of 2
[2025-06-10T16:43:45.714+0200] {taskinstance.py:2890} INFO - Executing <Task(PythonOperator): data_quality_check> on 2025-06-10 14:42:33.619738+00:00
[2025-06-10T16:43:45.716+0200] {standard_task_runner.py:72} INFO - Started process 44690 to run task
[2025-06-10T16:43:45.719+0200] {standard_task_runner.py:104} INFO - Running: ['airflow', 'tasks', 'run', 'case4', 'data_quality_check', 'manual__2025-06-10T14:42:33.619738+00:00', '--job-id', '53', '--raw', '--subdir', 'DAGS_FOLDER/case4.py', '--cfg-path', '/var/folders/sj/kmk_wl3517d377606n_z382h0000gp/T/tmp9vt625_p']
[2025-06-10T16:43:45.720+0200] {standard_task_runner.py:105} INFO - Job 53: Subtask data_quality_check
[2025-06-10T16:43:45.743+0200] {task_command.py:467} INFO - Running <TaskInstance: case4.data_quality_check manual__2025-06-10T14:42:33.619738+00:00 [running]> on host LGLXN9TVJX
[2025-06-10T16:43:45.763+0200] {taskinstance.py:3134} INFO - Exporting env vars: AIRFLOW_CTX_DAG_EMAIL='tayfun.simsek@mhp.com' AIRFLOW_CTX_DAG_OWNER='airflow' AIRFLOW_CTX_DAG_ID='case4' AIRFLOW_CTX_TASK_ID='data_quality_check' AIRFLOW_CTX_EXECUTION_DATE='2025-06-10T14:42:33.619738+00:00' AIRFLOW_CTX_TRY_NUMBER='1' AIRFLOW_CTX_DAG_RUN_ID='manual__2025-06-10T14:42:33.619738+00:00'
[2025-06-10T16:43:45.763+0200] {taskinstance.py:732} INFO - ::endgroup::
[2025-06-10T16:43:45.772+0200] {logging_mixin.py:190} WARNING - /Users/tsimsek/Library/Python/3.9/lib/python/site-packages/airflow/utils/operator_helpers.py:175 AirflowContextDeprecationWarning: Accessing 'execution_date' from the template is deprecated and will be removed in a future version. Please use 'data_interval_start' or 'logical_date' instead.
[2025-06-10T16:43:45.772+0200] {taskinstance.py:3313} ERROR - Task failed with exception
Traceback (most recent call last):
  File "/Users/tsimsek/Library/Python/3.9/lib/python/site-packages/airflow/models/taskinstance.py", line 768, in _execute_task
    result = _execute_callable(context=context, **execute_callable_kwargs)
  File "/Users/tsimsek/Library/Python/3.9/lib/python/site-packages/airflow/models/taskinstance.py", line 734, in _execute_callable
    return ExecutionCallableRunner(
  File "/Users/tsimsek/Library/Python/3.9/lib/python/site-packages/airflow/utils/operator_helpers.py", line 252, in run
    return self.func(*args, **kwargs)
  File "/Users/tsimsek/Library/Python/3.9/lib/python/site-packages/airflow/models/baseoperator.py", line 424, in wrapper
    return func(self, *args, **kwargs)
  File "/Users/tsimsek/Library/Python/3.9/lib/python/site-packages/airflow/operators/python.py", line 238, in execute
    return_value = self.execute_callable()
  File "/Users/tsimsek/Library/Python/3.9/lib/python/site-packages/airflow/operators/python.py", line 256, in execute_callable
    return runner.run(*self.op_args, **self.op_kwargs)
  File "/Users/tsimsek/Library/Python/3.9/lib/python/site-packages/airflow/utils/operator_helpers.py", line 252, in run
    return self.func(*args, **kwargs)
  File "/Users/tsimsek/airflow/dags/utils.py", line 139, in case4_check_data_quality
    parquet_path = os.path.join(base_dir, f"../data/processed/taxi_data_{year}-{month:02d}-{day:02d}_enriched.parquet")
NameError: name 'base_dir' is not defined
[2025-06-10T16:43:45.793+0200] {taskinstance.py:1226} INFO - Marking task as UP_FOR_RETRY. dag_id=case4, task_id=data_quality_check, run_id=manual__2025-06-10T14:42:33.619738+00:00, execution_date=20250610T144233, start_date=20250610T144345, end_date=20250610T144345
[2025-06-10T16:43:45.799+0200] {taskinstance.py:341} INFO - ::group::Post task execution logs
[2025-06-10T16:43:45.800+0200] {standard_task_runner.py:124} ERROR - Failed to execute job 53 for task data_quality_check (name 'base_dir' is not defined; 44690)
Traceback (most recent call last):
  File "/Users/tsimsek/Library/Python/3.9/lib/python/site-packages/airflow/task/task_runner/standard_task_runner.py", line 117, in _start_by_fork
    ret = args.func(args, dag=self.dag)
  File "/Users/tsimsek/Library/Python/3.9/lib/python/site-packages/airflow/cli/cli_config.py", line 49, in command
    return func(*args, **kwargs)
  File "/Users/tsimsek/Library/Python/3.9/lib/python/site-packages/airflow/utils/cli.py", line 116, in wrapper
    return f(*args, **kwargs)
  File "/Users/tsimsek/Library/Python/3.9/lib/python/site-packages/airflow/cli/commands/task_command.py", line 483, in task_run
    task_return_code = _run_task_by_selected_method(args, _dag, ti)
  File "/Users/tsimsek/Library/Python/3.9/lib/python/site-packages/airflow/cli/commands/task_command.py", line 256, in _run_task_by_selected_method
    return _run_raw_task(args, ti)
  File "/Users/tsimsek/Library/Python/3.9/lib/python/site-packages/airflow/cli/commands/task_command.py", line 341, in _run_raw_task
    return ti._run_raw_task(
  File "/Users/tsimsek/Library/Python/3.9/lib/python/site-packages/airflow/utils/session.py", line 97, in wrapper
    return func(*args, session=session, **kwargs)
  File "/Users/tsimsek/Library/Python/3.9/lib/python/site-packages/airflow/models/taskinstance.py", line 3006, in _run_raw_task
    return _run_raw_task(
  File "/Users/tsimsek/Library/Python/3.9/lib/python/site-packages/airflow/models/taskinstance.py", line 274, in _run_raw_task
    TaskInstance._execute_task_with_callbacks(
  File "/Users/tsimsek/Library/Python/3.9/lib/python/site-packages/airflow/models/taskinstance.py", line 3161, in _execute_task_with_callbacks
    result = self._execute_task(context, task_orig)
  File "/Users/tsimsek/Library/Python/3.9/lib/python/site-packages/airflow/models/taskinstance.py", line 3185, in _execute_task
    return _execute_task(self, context, task_orig)
  File "/Users/tsimsek/Library/Python/3.9/lib/python/site-packages/airflow/models/taskinstance.py", line 768, in _execute_task
    result = _execute_callable(context=context, **execute_callable_kwargs)
  File "/Users/tsimsek/Library/Python/3.9/lib/python/site-packages/airflow/models/taskinstance.py", line 734, in _execute_callable
    return ExecutionCallableRunner(
  File "/Users/tsimsek/Library/Python/3.9/lib/python/site-packages/airflow/utils/operator_helpers.py", line 252, in run
    return self.func(*args, **kwargs)
  File "/Users/tsimsek/Library/Python/3.9/lib/python/site-packages/airflow/models/baseoperator.py", line 424, in wrapper
    return func(self, *args, **kwargs)
  File "/Users/tsimsek/Library/Python/3.9/lib/python/site-packages/airflow/operators/python.py", line 238, in execute
    return_value = self.execute_callable()
  File "/Users/tsimsek/Library/Python/3.9/lib/python/site-packages/airflow/operators/python.py", line 256, in execute_callable
    return runner.run(*self.op_args, **self.op_kwargs)
  File "/Users/tsimsek/Library/Python/3.9/lib/python/site-packages/airflow/utils/operator_helpers.py", line 252, in run
    return self.func(*args, **kwargs)
  File "/Users/tsimsek/airflow/dags/utils.py", line 139, in case4_check_data_quality
    parquet_path = os.path.join(base_dir, f"../data/processed/taxi_data_{year}-{month:02d}-{day:02d}_enriched.parquet")
NameError: name 'base_dir' is not defined
[2025-06-10T16:43:45.855+0200] {local_task_job_runner.py:266} INFO - Task exited with return code 1
[2025-06-10T16:43:45.866+0200] {taskinstance.py:3901} INFO - 0 downstream tasks scheduled from follow-on schedule check
[2025-06-10T16:43:45.866+0200] {local_task_job_runner.py:245} INFO - ::endgroup::
